<?xml version="1.0" encoding="UTF-8"?>
<!-- Generated by org.testng.reporters.JUnitXMLReporter -->
<testsuite hostname="XULE" name="Jiekou" tests="3" failures="2" timestamp="25 Oct 2018 17:04:01 GMT" time="0.284" errors="0">
  <testcase name="a" time="0.136" classname="demo.TESTS">
    <failure type="java.lang.AssertionError" message="expected [2] but found [1]">
      <![CDATA[java.lang.AssertionError: expected [2] but found [1]
	at demo.TESTS.a(TESTS.java:13)
	at com.intellij.rt.execution.application.AppMain.main(AppMain.java:147)
... Removed 33 stack frames]]>
    </failure>
  </testcase> <!-- a -->
  <testcase name="b" time="0.007" classname="demo.TESTS"/>
  <testcase name="log" time="0.016" classname="demo.TESTS">
    <failure type="java.lang.RuntimeException" message="这是我自己运行的异常">
      <![CDATA[java.lang.RuntimeException: 这是我自己运行的异常
	at demo.TESTS.log(TESTS.java:22)
	at com.intellij.rt.execution.application.AppMain.main(AppMain.java:147)
... Removed 27 stack frames]]>
    </failure>
  </testcase> <!-- log -->
</testsuite> <!-- Jiekou -->
